Workbook

Sheet Top 50
A1: Rank | B1: Image | C1: Product name | D1: Category | E1: Material (as stated) | F1: Seller / Brand | G1: Channel | H1: Current price (USD) | I1: Sale / list price (USD) | J1: Size / dimensions (as stated) | K1: Rating (of 5) | L1: Review count | M1: Best-seller proxy (type + value) | N1: Product URL | O1: Image URL | P1: Fetched at | Q1: Status / notes
A2: 1 | C2: Everett Long Wood Foyer Table | D2: Console table | E2: Acacia, pine, MDF, plywood and veneer | F2: World Market | G2: World Market | H2: 449.99 | J2: 71"W x 16"D x 32"H, 65 lb | K2: 4.8 | L2: 718 | M2: [Tier A] 718 reviews, 4.8 avg; World Market 'Top Sellers' sort #1 for search 'wood console table' | N2: https://www.worldmarket.com/p/everett-long-wood-foyer-table-129713.html | O2: https://www.worldmarket.com/on/demandware.static/-/Sites-wm-master-catalog/default/dw17f31133/images/large/129713_weatherednatural_v1.jpg?sw=400&sh=400&sm=fit&sfrm=jpg&q=80 | P2: 2026-09-25 09:42 UTC | Q2: OK | mixed/engineered construction; volume benchmark
A3: 2 | C3: Chloe Wood Side Table | D3: Side / end table | E3: Rubberwood | F3: World Market | G3: World Market | H3: 59.99 | J3: 12" sq x 24"H, 13.2 lb | K3: 4.7 | L3: 413 | M3: [Tier A] 413 reviews, 4.7 avg; World Market 'Top Sellers' sort #5 for search 'wood side table'; product copy says 'a World Market bestseller' | N3: https://www.worldmarket.com/p/chloe-wood-side-table-128427.html | O3: https://www.worldmarket.com/on/demandware.static/-/Sites-wm-master-catalog/default/dw9d25bc33/images/large/128427_mahogony_v1.jpg?sw=400&sh=400&sm=fit&sfrm=jpg&q=80 | P3: 2026-09-25 09:42 UTC | Q3: OK | not carved / not Indian-style; volume benchmark for budget end tables
A4: 3 | C4: Augustus Wood Library Bookshelf | D4: Bookshelf | E4: Rubber wood and veneer | F4: World Market | G4: World Market | H4: 799.99 | J4: 47"W x 17.5"D x 90"H, 199 lb | K4: 4.4 | L4: 221 | M4: [Tier A] 221 reviews, 4.4 avg; World Market 'Top Sellers' sort #3 for search 'wood bookshelf' | N4: https://www.worldmarket.com/p/augustus-wood-library-bookshelf-130791.html | O4: https://www.worldmarket.com/on/demandware.static/-/Sites-wm-master-catalog/default/dwcc8d3441/images/large/130791_roastedcocoa_v1.jpg?sw=400&sh=400&sm=fit&sfrm=jpg&q=80 | P4: 2026-09-25 09:42 UTC | Q4: OK | not carved; volume benchmark
A5: 4 | C5: Sansur Rustic Pecan Live Edge Wood Console Table | D5: Console table | E5: Suar wood, composite wood, suar veneer | F5: World Market | G5: World Market | H5: 174.99 | I5: 399.99 | J5: 58"W x 16"D x 30.1"H | K5: 4.9 | L5: 145 | M5: [Tier A] 145 reviews, 4.9 avg; World Market 'Top Sellers' sort #8 for search 'wood console table' | N5: https://www.worldmarket.com/p/sansur-rustic-pecan-live-edge-wood-console-table-565911.html | O5: https://www.worldmarket.com/on/demandware.static/-/Sites-wm-master-catalog/default/dw13495290/images/large/85113_XXX_v1.jpg?sw=400&sh=400&sm=fit&sfrm=jpg&q=80 | P5: 2026-09-25 09:42 UTC | Q5: OK | tile status: out of stock | on sale (list 399.99)
A6: 5 | C6: Extra Large Acacia Wood Paddle Cutting Board | D6: Kitchen & serveware | E6: Acacia wood | F6: World Market | G6: World Market | H6: 59.99 | J6: 13.75"W x 35"L | K6: 4.9 | L6: 87 | M6: [Tier B] 87 reviews, 4.9 avg; World Market 'Top Sellers' sort #13 for search 'wood cutting board' | N6: https://www.worldmarket.com/p/extra-large-acacia-wood-paddle-cutting-board-544486.html | O6: https://www.worldmarket.com/on/demandware.static/-/Sites-wm-master-catalog/default/dw6910c7ec/images/large/69129_XXX_v1.jpg?sw=400&sh=400&sm=fit&sfrm=jpg&q=80 | P6: 2026-09-25 09:42 UTC | Q6: OK
A7: 6 | C7: Colette Round Wood Ottoman Tray | D7: Kitchen & serveware | E7: Acacia wood, handcrafted in India | F7: World Market | G7: World Market | H7: 69.99 | J7: 24" dia x 2"H, 10 lb | K7: 5 | L7: 64 | M7: [Tier B] 64 reviews, 5.0 avg; World Market 'Top Sellers' sort #2 for search 'wood tray' | N7: https://www.worldmarket.com/p/colette-round-wood-ottoman-tray-125094.html | O7: https://www.worldmarket.com/on/demandware.static/-/Sites-wm-master-catalog/default/dwba16ec6d/images/large/125094_black_v1.jpg?sw=400&sh=400&sm=fit&sfrm=jpg&q=80 | P7: 2026-09-25 09:43 UTC | Q7: OK
A8: 7 | C8: Teakhaus Large Edge Grain Wood Trencher Cutting Board | D8: Kitchen & serveware | E8: FSC-certified teak, edge grain | F8: Teakhaus (sold at World Market) | G8: World Market | H8: 42.99 | J8: 14"W x 18"L x 0.75"H | K8: 4.5 | L8: 62 | M8: [Tier B] 62 reviews, 4.5 avg; World Market 'Top Sellers' sort #5 for search 'wood cutting board' | N8: https://www.worldmarket.com/p/teakhaus-large-edge-grain-wood-trencher-cutting-board-592151.html | O8: https://www.worldmarket.com/on/demandware.static/-/Sites-wm-master-catalog/default/dwf94072da/images/large/96544_XXX_v1.jpg?sw=400&sh=400&sm=fit&sfrm=jpg&q=80 | P8: 2026-09-25 09:42 UTC | Q8: OK
A9: 8 | C9: Dane Acacia Mid Century Modular Bookshelf with Cabinet | D9: Bookshelf | E9: Solid acacia wood | F9: World Market | G9: World Market | H9: 649.99 | J9: 39.5"W x 13.75"D x 70"H, 119 lb | K9: 4.2 | L9: 60 | M9: [Tier B] 60 reviews, 4.2 avg; World Market 'Top Sellers' sort #5 for search 'wood bookshelf' | N9: https://www.worldmarket.com/p/dane-acacia-mid-century-modular-bookshelf-with-cabinet-131794.html | O9: https://www.worldmarket.com/on/demandware.static/-/Sites-wm-master-catalog/default/dw719a03e5/images/large/131794_walnut_v1.jpg?sw=400&sh=400&sm=fit&sfrm=jpg&q=80 | P9: 2026-09-25 09:42 UTC | Q9: OK
A10: 9 | C10: Lansing Hazelnut Mango Wood Asymmetrical Side Table | D10: Side / end table | E10: Handcrafted by Indian artisans; product page title says mango wood, copy/spec says acacia | F10: World Market | G10: World Market | H10: 149.99 | J10: 19"W x 13"D x 19"H, 24.5 lb | K10: 4.8 | L10: 53 | M10: [Tier B] 53 reviews, 4.8 avg; World Market 'Top Sellers' sort #1 for search 'wood side table' | N10: https://www.worldmarket.com/p/lansing-hazelnut-mango-wood-asymmetrical-side-table-634446.html | O10: https://www.worldmarket.com/on/demandware.static/-/Sites-wm-master-catalog/default/dwa54000f2/images/large/122634_XXX_v1.jpg?sw=400&sh=400&sm=fit&sfrm=jpg&q=80 | P10: 2026-09-25 09:41 UTC | Q10: OK
A11: 10 | C11: Tunisian Olive Wood Cutting Board | D11: Kitchen & serveware | E11: Olive wood (made in Tunisia) | F11: World Market | G11: World Market | H11: 29.99 | J11: ~8.7"W x 15.8"L | K11: 4.6 | L11: 47 | M11: [Tier B] 47 reviews, 4.6 avg; World Market 'Top Sellers' sort #10 for search 'wood cutting board' | N11: https://www.worldmarket.com/p/tunisian-olive-wood-cutting-board-585206.html | O11: https://www.worldmarket.com/on/demandware.static/-/Sites-wm-master-catalog/default/dwbaa4ef9b/images/large/92688_XXX_v1.jpg?sw=400&sh=400&sm=fit&sfrm=jpg&q=80 | P11: 2026-09-25 09:42 UTC | Q11: OK
A12: 11 | C12: CRAFT Avni Arched Natural Carved Wood Floral Storage Cabinet | D12: Storage cabinet / chest | E12: Mango wood, hand-carved floral cutwork, natural finish | F12: World Market | G12: World Market | H12: 1499.99 | J12: 32"W x 16"D x 72"H, 105 lb | K12: 4.5 | L12: 43 | M12: [Tier B] 43 reviews, 4.5 avg; World Market 'Top Sellers' sort #29 for search 'carved wood' | N12: https://www.worldmarket.com/p/craft-avni-arched-natural-carved-wood-floral-storage-cabinet-598655.html | O12: https://www.worldmarket.com/on/demandware.static/-/Sites-wm-master-catalog/default/dwbb8342d8/images/large/100650_XXX_v1.jpg?sw=400&sh=400&sm=fit&sfrm=jpg&q=80 | P12: 2026-09-25 09:42 UTC | Q12: OK
A13: 12 | C13: Paulownia Wood Tripod Plant Stand | D13: Planter / plant stand | E13: Paulownia wood | F13: World Market | G13: World Market | H13: 29.99 | J13: 11.5" dia x 5"H | K13: 4.9 | L13: 40 | M13: [Tier B] 40 reviews, 4.9 avg; World Market 'Top Sellers' sort #6 for search 'wood plant stand' | N13: https://www.worldmarket.com/p/paulownia-wood-tripod-plant-stand-607343.html | O13: https://www.worldmarket.com/on/demandware.static/-/Sites-wm-master-catalog/default/dw92e65f20/images/large/106976_XXX_v1.jpg?sw=400&sh=400&sm=fit&sfrm=jpg&q=80 | P13: 2026-09-25 09:43 UTC | Q13: OK
A14: 13 | C14: Mango Wood Footed Serving Tray | D14: Kitchen & serveware | E14: Solid mango wood, burnt finish, made in India | F14: World Market | G14: World Market | H14: 34.99 | J14: Medium 6"W x 12"L x 2.5"H (also large) | K14: 4.9 | L14: 38 | M14: [Tier B] 38 reviews, 4.9 avg; World Market 'Top Sellers' sort #28 for search 'wood tray' | N14: https://www.worldmarket.com/p/mango-wood-footed-serving-tray-113191.html | O14: https://www.worldmarket.com/on/demandware.static/-/Sites-wm-master-catalog/default/dwc98cff47/images/large/113191_XXX_v1.jpg?sw=400&sh=400&sm=fit&sfrm=jpg&q=80 | P14: 2026-09-25 09:42 UTC | Q14: OK
A15: 14 | C15: Anish Round Natural Wood Ribbed Pedestal Side Table | D15: Side / end table | E15: Handcrafted of natural mango wood | F15: World Market | G15: World Market | H15: 149.99 | J15: 14" dia x 21"H, 17 lb | K15: 5 | L15: 33 | M15: [Tier B] 33 reviews, 5.0 avg; World Market 'Top Sellers' sort #7 for search 'wood side table' | N15: https://www.worldmarket.com/p/anish-round-natural-wood-ribbed-pedestal-side-table-635511.html | O15: https://www.worldmarket.com/on/demandware.static/-/Sites-wm-master-catalog/default/dwa2ce24df/images/large/122622_XXX_v1.jpg?sw=400&sh=400&sm=fit&sfrm=jpg&q=80 | P15: 2026-09-25 09:42 UTC | Q15: OK
A16: 15 | C16: CRAFT Short Teal Carved Wood Peacock Storage Cabinet | D16: Storage cabinet / chest | E16: Mango wood, hand-carved peacock, distressed teal, metal stand | F16: World Market | G16: World Market | H16: 699.99 | J16: 32"W x 16"D x 42"H, 77 lb | K16: 4.6 | L16: 31 | M16: [Tier B] 31 reviews, 4.6 avg; World Market 'Top Sellers' sort #10 for search 'carved wood' | N16: https://www.worldmarket.com/p/craft-short-teal-carved-wood-peacock-storage-cabinet-638915.html | O16: https://www.worldmarket.com/on/demandware.static/-/Sites-wm-master-catalog/default/dw56b8bb65/images/large/125084_XXX_v1.jpg?sw=400&sh=400&sm=fit&sfrm=jpg&q=80 | P16: 2026-09-25 09:42 UTC | Q16: OK
A17: 16 | C17: Thailand Acacia Wood Serving Bowl | D17: Kitchen & serveware | E17: Acacia wood (made in Thailand) | F17: World Market | G17: World Market | H17: 27.98 | I17: 39.99 | J17: 12" dia x 5"H | K17: 4.7 | L17: 30 | M17: [Tier B] 30 reviews, 4.7 avg; World Market 'Top Sellers' sort #7 for search 'wood serving bowl' | N17: https://www.worldmarket.com/p/thailand-acacia-wood-serving-bowl-558030.html | O17: https://www.worldmarket.com/on/demandware.static/-/Sites-wm-master-catalog/default/dw80243635/images/large/77838_XXX_v1.tif?sw=400&sh=400&sm=fit&sfrm=jpg&q=80 | P17: 2026-09-25 09:43 UTC | Q17: OK
A18: 17 | C18: CRAFT Multicolor Carved Wood Elephant Floor Decor | D18: Décor figure | E18: Mango wood, hand-carved & hand-painted, India | F18: World Market | G18: World Market | H18: 249.99 | J18: 24.5"W x 9"D x 23.5"H | K18: 5 | L18: 24 | M18: [Tier B] 24 reviews, 5.0 avg; World Market 'Top Sellers' sort #16 for search 'wood side table' | N18: https://www.worldmarket.com/p/craft-multicolor-carved-wood-elephant-floor-decor-634762.html | O18: https://www.worldmarket.com/on/demandware.static/-/Sites-wm-master-catalog/default/dwfeb04c92/images/large/124485_XXX_v1.jpg?sw=400&sh=400&sm=fit&sfrm=jpg&q=80 | P18: 2026-09-25 09:43 UTC | Q18: OK
A19: 18 | C19: Brentwood Round Natural Wood Pedestal End Table | D19: Side / end table | E19: Natural mango wood | F19: World Market | G19: World Market | H19: 149.99 | J19: 17" dia x 23"H, 14 lb | K19: 4.9 | L19: 23 | M19: [Tier B] 23 reviews, 4.9 avg; World Market 'Top Sellers' sort #3 for search 'wood side table' | N19: https://www.worldmarket.com/p/brentwood-round-natural-wood-pedestal-end-table-639923.html | O19: https://www.worldmarket.com/dw/image/v2/BJWT_PRD/on/demandware.static/-/Sites-wm-master-catalog/default/dw9e8964cf/images/large/125478_XXX_v1.jpg?sw=385&sh=385&sm=fit&sfrm=jpg&q=80 | P19: 2026-09-25 09:41 UTC | Q19: OK
A20: 19 | C20: Carved Mango Wood Group of Figures Decor | D20: Décor figure | E20: Hand-carved mango wood, central India | F20: World Market | G20: World Market | H20: 89.99 | J20: 24.2"W x 3.7"D x 13.3"H | K20: 5 | L20: 23 | M20: [Tier B] 23 reviews, 5.0 avg; World Market 'Top Sellers' sort #26 for search 'mango wood' | N20: https://www.worldmarket.com/p/carved-mango-wood-group-of-figures-decor-591505.html | O20: https://www.worldmarket.com/on/demandware.static/-/Sites-wm-master-catalog/default/dw39ca1048/images/large/95893_XXX_v1.jpg?sw=400&sh=400&sm=fit&sfrm=jpg&q=80 | P20: 2026-09-25 09:43 UTC | Q20: OK
A21: 20 | C21: White Wooden Pooja Mandir with Brass Bells & Doors | D21: Mandir / pooja unit | E21: Solid mango wood, hand-painted white & gold (as stated) | F21: Urli Utsav Decor | G21: Urli Utsav Decor (own site) | H21: 390 | J21: 30 in H (as stated by seller; see page) | M21: [Tier B] Retailer 'Best selling' sort: #1 in /collections/wooden-pooja-mandirs-bajot-chowki-usa (sort_by=best-selling). No public rating/review count on page | N21: https://urliutsav.com/products/white-pooja-mandir-brass-bells | O21: https://cdn.shopify.com/s/files/1/0579/1534/2899/files/whitemandir-urliutsav12.jpg?v=1768770308 | P21: 2026-09-25 09:39 UTC | Q21: OK
A22: 21 | C22: 5' x 2' Natural Teak Finish Mandir with doors | D22: Mandir / pooja unit | E22: Engineered wood, plywood, texture finish (as stated; "natural teak finish") | F22: The Mandir Store | G22: The Mandir Store (own site) | H22: 899 | I22: 1099 | J22: 5 ft x 2 ft (per title) | M22: [Tier B] Retailer 'Best selling' sort: #1 in /collections/pooja-mandirs (sort_by=best-selling). No public rating/review count on page | N22: https://themandirstore.us/products/5-x-2-natural-teak-finish-mandir-with-doors | O22: https://cdn.shopify.com/s/files/1/0558/5997/0197/files/image_11.png?v=1785515295 | P22: 2026-09-25 09:39 UTC | Q22: OK | not solid wood per seller copy
A23: 22 | C23: Wooden White Pooja Chowki - 18x18x6.5-Inches Gold Bajot | D23: Pooja stool / chowki | E23: Premium mango wood, hand-painted white & gold | F23: Urli Utsav Decor | G23: Urli Utsav Decor (own site) | H23: 126 | J23: 18 x 18 x 6.5 in | M23: [Tier B] Retailer 'Best selling' sort: #1 in /collections/chowki-bajot-pooja-stools (sort_by=best-selling). No public rating/review count on page | N23: https://urliutsav.com/products/18x18x6-5-wooden-pooja-chowki-bajot | O23: https://cdn.shopify.com/s/files/1/0579/1534/2899/files/PureWhiteChowki-UrliUtsav-main.jpg?v=1769372415 | P23: 2026-09-25 09:39 UTC | Q23: OK
A24: 23 | C24: Hand-Painted Jharokha Mirror – 12x10 Inches, 8 Colours | D24: Jharokha / carved wall piece | E24: MDF frame with glass mirror, hand-painted (as stated) | F24: Urli Utsav Decor | G24: Urli Utsav Decor (own site) | H24: 60 | J24: 12" x 10" x 10 mm | M24: [Tier B] Retailer 'Best selling' sort: #1 in /collections/handcrafted-rajasthani-jharokha-decor (sort_by=best-selling). No public rating/review count on page | N24: https://urliutsav.com/products/hand-painted-jharokha-mirror-12x10 | O24: https://cdn.shopify.com/s/files/1/0579/1534/2899/files/Jharokha-UrliUtsav-1.jpg?v=1739499307 | P24: 2026-09-25 09:39 UTC | Q24: OK | MDF, not solid wood
A25: 24 | C25: Cordoba Vintage Carved Mirror | D25: Carved / wooden mirror | E25: Solid reclaimed teak, carved frame | F25: World Interiors | G25: World Interiors (own site) | H25: 500 | J25: 37"W x 1.5"D x 44.5"H | M25: [Tier B] Retailer 'Best selling' sort: #1 in /collections/mirrors (sort_by=best-selling). No public rating/review count on page | N25: https://worldinteriors.com/products/cordoba-vintage-carved-mirror | O25: https://cdn.shopify.com/s/files/1/1871/5825/products/FIZ-MR44-1.jpg?v=1740007620 | P25: 2026-09-25 09:39 UTC | Q25: OK
A26: 25 | C26: Agra Reclaimed Wood Mirror | D26: Carved / wooden mirror | E26: Old reclaimed wood frame (floor mirror) | F26: Timbergirl | G26: Timbergirl (own site) | H26: 499.99 | J26: 60" H x 30" W (as stated) | M26: [Tier B] Retailer 'Best selling' sort: #1 in /collections/mirrors (sort_by=best-selling). No public rating/review count on page | N26: https://timbergirl.com/products/agra-reclaimed-wood-mirror | O26: https://cdn.shopify.com/s/files/1/0681/8414/6142/files/AA80000__99674.1710668117.1280.1280.jpg?v=1719700760 | P26: 2026-09-25 09:39 UTC | Q26: OK (price shown; SOLD OUT at fetch)
A27: 26 | C27: Handcrafted Reclaimed Wood Wall Mirror – Rustic Rectangular Farmhouse Décor for Bathroom, Bedroom and Entryway | D27: Carved / wooden mirror | E27: Reclaimed wood frame | F27: The Vintage Realm | G27: The Vintage Realm (own site) | H27: 103.95 | I27: 135 | J27: Multiple sizes (price is lowest variant) | M27: [Tier B] Retailer 'Best selling' sort: #1 in /collections/mirror-frames (sort_by=best-selling). No public rating/review count on page | N27: https://thevintagerealm.com/products/handcrafted-reclaimed-wood-wall-mirror-rustic-rectangular-farmhouse-decor-for-bathroom-bedroom-and-entryway | O27: https://cdn.shopify.com/s/files/1/0626/9196/7157/files/handcrafted-reclaimed-wood-wall-mirror-rustic-rectangular-farmhouse-decor-for-bathroom-bedroom-and-entrywayprod-184-01-5329572.webp?v=1787686106 | P27: 2026-09-25 09:39 UTC | Q27: OK | price = lowest of several size variants
A28: 27 | C28: Mango Wood Coffee Table | D28: Coffee table | E28: Solid mango wood, handmade | F28: Timbergirl | G28: Timbergirl (own site) | H28: 799.99 | J28: 16"H x 53"W x 28"D, 45 lb | M28: [Tier B] Retailer 'Best selling' sort: #1 in /collections/coffee-table (sort_by=best-selling). No public rating/review count on page | N28: https://timbergirl.com/products/mango-wood-coffee-table | O28: https://cdn.shopify.com/s/files/1/0681/8414/6142/files/SUN_0229.jpg?v=1737567298 | P28: 2026-09-25 09:39 UTC | Q28: OK (price shown; SOLD OUT at fetch)
A29: 28 | C29: Rustic Low Coffee Table | D29: Coffee table | E29: Reclaimed wood | F29: The Vintage Realm (Modern Karigar) | G29: The Vintage Realm (own site) | H29: 789.25 | I29: 1025 | J29: Multiple sizes (price = lowest variant) | M29: [Tier B] Retailer 'Best selling' sort: #1 in /collections/coffee-table (sort_by=best-selling). No public rating/review count on page | N29: https://thevintagerealm.com/products/rustic-low-coffee-table | O29: https://cdn.shopify.com/s/files/1/0626/9196/7157/files/rustic-low-coffee-tableprod-159-01-6418904.webp?v=1780394286 | P29: 2026-09-25 09:39 UTC | Q29: OK | price = lowest of several size variants
A30: 29 | C30: Solid Natural Mango Wood Bench - 60" | D30: Bench | E30: Solid mango wood | F30: Timbergirl | G30: Timbergirl (own site) | H30: 399.99 | J30: 18"H x 60"W x 16"D | M30: [Tier B] Retailer 'Best selling' sort: #1 in /collections/dining-benches-1 (sort_by=best-selling). No public rating/review count on page | N30: https://timbergirl.com/products/solid-natural-mango-wood-bench-60 | O30: https://cdn.shopify.com/s/files/1/0681/8414/6142/files/SUN_2449_2.jpg?v=1753892427 | P30: 2026-09-25 09:39 UTC | Q30: OK
A31: 30 | C31: Solid Mango Wood Tall Bookcase | D31: Bookshelf | E31: Recycled/rough-sawn mango wood with iron | F31: Timbergirl | G31: Timbergirl (own site) | H31: 799.99 | J31: 71"H x 23.75"W x 15.75"D, 80 lb | M31: [Tier B] Retailer 'Best selling' sort: #1 in /collections/towers-bookcases (sort_by=best-selling). No public rating/review count on page | N31: https://timbergirl.com/products/reclaimed-wood-tall-rack | O31: https://cdn.shopify.com/s/files/1/0681/8414/6142/files/86911955_01.png?v=1731354540 | P31: 2026-09-25 09:39 UTC | Q31: OK
A32: 31 | C32: Blayne 78-Inch Tall Live Edge Bookshelf | D32: Bookshelf | E32: Acacia shelves, cast-iron frame | F32: World Interiors | G32: World Interiors (own site) | H32: 1095 | J32: 78 in tall (per title) | M32: [Tier B] Retailer 'Best selling' sort: #1 in /collections/bookcases-shelving (sort_by=best-selling). No public rating/review count on page | N32: https://worldinteriors.com/products/blayne-78-inch-tall-live-edge-bookshelf | O32: https://cdn.shopify.com/s/files/1/1871/5825/products/ZWBABS34RW_add.jpg?v=1740007621 | P32: 2026-09-25 09:39 UTC | Q32: OK
A33: 32 | C33: Carved Wooden Mirror | D33: Carved / wooden mirror | E33: Solid wood, hand-carved (as stated); made in India | F33: TimorGreen (sold at Timbergirl) | G33: Timbergirl (own site) | H33: 1171.99 | J33: As stated: 2"H x 81"L x 45"W (seller order looks inconsistent; check page) | M33: [Tier B] Retailer 'Best selling' sort: #2 in /collections/mirrors (sort_by=best-selling). No public rating/review count on page | N33: https://timbergirl.com/products/rhu-home-carved-wooden-mirror | O33: https://cdn.shopify.com/s/files/1/0681/8414/6142/files/AAM257_3_Web__79113__67594.1650996873.1280.1280.jpg?v=1719703009 | P33: 2026-09-25 09:39 UTC | Q33: OK
A34: 33 | C34: Summit 54" Modern Coffee Table in Capri Sheesham | D34: Coffee table | E34: 100% solid sheesham, iron base | F34: World Interiors | G34: World Interiors (own site) | H34: 824 | J34: 54"W x 28"D x 18"H | M34: [Tier B] Retailer 'Best selling' sort: #2 in /collections/sheesham-wood (sort_by=best-selling). No public rating/review count on page | N34: https://worldinteriors.com/products/summit-54-modern-coffee-table-in-capri-sheesham | O34: https://cdn.shopify.com/s/files/1/1871/5825/files/fsvl-ct54cs_3q1.jpg?v=1740006913 | P34: 2026-09-25 09:39 UTC | Q34: OK
A35: 34 | C35: Timbergirl Old reclaimed wood Console Table | D35: Console table | E35: Reclaimed wood (saal) with iron handles | F35: Timbergirl | G35: Timbergirl (own site) | H35: 799.99 | I35: 899.99 | J35: 60"W x 16"D x 31.5"H, 50 lb | M35: [Tier B] Retailer 'Best selling' sort: #2 in /collections/console-tables (sort_by=best-selling). No public rating/review count on page | N35: https://timbergirl.com/products/timbergirl-old-reclaimed-wood-console-table | O35: https://cdn.shopify.com/s/files/1/0681/8414/6142/files/SUN_AA1473_2.png?v=1729543126 | P35: 2026-09-25 09:39 UTC | Q35: OK
A36: 35 | C36: Timbergirl Suman Rustic Multicolor Bench - 50" | D36: Bench | E36: Solid mango wood, rustic multicolour | F36: Timbergirl | G36: Timbergirl (own site) | H36: 329.99 | J36: 18"H x 50"W x 16"D (60" W also available) | M36: [Tier B] Retailer 'Best selling' sort: #2 in /collections/dining-benches-1 (sort_by=best-selling). No public rating/review count on page | N36: https://timbergirl.com/products/timbergirl-suman-rustic-multicolor-bench-50 | O36: https://cdn.shopify.com/s/files/1/0681/8414/6142/files/SUN_7914.jpg?v=1729703958 | P36: 2026-09-25 09:39 UTC | Q36: OK
A37: 36 | C37: White and Gold Wall Hanging Pooja Mandir | D37: Mandir / pooja unit | E37: Solid mango wood, hand-painted, carved jaali detailing | F37: Urli Utsav Decor | G37: Urli Utsav Decor (own site) | H37: 275 | J37: Two sizes; wall-hanging or floor-standing (see page) | M37: [Tier B] Retailer 'Best selling' sort: #3 in /collections/wooden-pooja-mandirs-bajot-chowki-usa (sort_by=best-selling). No public rating/review count on page | N37: https://urliutsav.com/products/compact-white-gold-wooden-temple | O37: https://cdn.shopify.com/s/files/1/0579/1534/2899/files/GoldMandir-8.jpg?v=1770973128 | P37: 2026-09-25 09:39 UTC | Q37: OK
A38: 37 | C38: 5' x 2' White Wooden Pooja Mandir with Doors for Home | D38: Mandir / pooja unit | E38: Engineered wood, plywood, white finish (as stated) | F38: The Mandir Store | G38: The Mandir Store (own site) | H38: 1099 | I38: 1399 | J38: 5 ft x 2 ft (per title) | M38: [Tier B] Retailer 'Best selling' sort: #3 in /collections/pooja-mandirs (sort_by=best-selling). No public rating/review count on page | N38: https://themandirstore.us/products/5-x-2-white-wooden-pooja-mandir-with-doors | O38: https://cdn.shopify.com/s/files/1/0558/5997/0197/files/image_12.png?v=1785515388 | P38: 2026-09-25 09:39 UTC | Q38: OK | seller copy: backorder from incoming container
A39: 38 | C39: Rajasthani Jharokha Mirror with Opening Doors – 20x16 Inches | D39: Jharokha / carved wall piece | E39: MDF panel with glass mirror; brass hinges (as stated) | F39: Urli Utsav Decor | G39: Urli Utsav Decor (own site) | H39: 160 | J39: 20" x 16" x 12 mm | M39: [Tier B] Retailer 'Best selling' sort: #3 in /collections/handcrafted-rajasthani-jharokha-decor (sort_by=best-selling). No public rating/review count on page | N39: https://urliutsav.com/products/rajasthani-jharokha-20x16-inches-mirror-frame | O39: https://cdn.shopify.com/s/files/1/0579/1534/2899/files/RajasthaniMirrorJharokha5.jpg?v=1735351936 | P39: 2026-09-25 09:39 UTC | Q39: OK | MDF, not solid wood
A40: 39 | C40: Seesham Wood Coffee Table | D40: Coffee table | E40: Solid sheesham wood, handmade | F40: Timbergirl | G40: Timbergirl (own site) | H40: 599.99 | J40: 16"H x 53"W x 28"D, 45 lb | M40: [Tier B] Retailer 'Best selling' sort: #3 in /collections/coffee-table (sort_by=best-selling). No public rating/review count on page | N40: https://timbergirl.com/products/seesham-wood-coffee-table | O40: https://cdn.shopify.com/s/files/1/0681/8414/6142/files/SUN_8086.jpg?v=1744654739 | P40: 2026-09-25 09:39 UTC | Q40: OK
...

Sheet Our target
A1: Rank | B1: Competitor product | C1: Competitor category | D1: Competitor price (USD) | E1: Our SKU | F1: Our product | G1: Our planned US price (USD) | H1: Gap % (ours vs competitor) | I1: Comment
A2: ='Top 50'!A2 -> 1 | B2: ='Top 50'!C2 -> Everett Long Wood Foyer Table | C2: ='Top 50'!D2 -> Console table | D2: =IF('Top 50'!H2="","",'Top 50'!H2) -> 449.99 | E2: S7 | F2: =IF(E2="","",INDEX($B$56:$B$66,MATCH(E2,$A$56:$A$66,0))) -> Console 120 | G2: =IF(E2="","",INDEX($C$56:$C$66,MATCH(E2,$A$56:$A$66,0))) -> 559 | H2: =IF(OR(G2="",D2=""),"",G2/D2-1) -> 0.24224983 | I2: Entryway console
A3: ='Top 50'!A3 -> 2 | B3: ='Top 50'!C3 -> Chloe Wood Side Table | C3: ='Top 50'!D3 -> Side / end table | D3: =IF('Top 50'!H3="","",'Top 50'!H3) -> 59.99 | E3: S6 | F3: =IF(E3="","",INDEX($B$56:$B$66,MATCH(E3,$A$56:$A$66,0))) -> Side table | G3: =IF(E3="","",INDEX($C$56:$C$66,MATCH(E3,$A$56:$A$66,0))) -> 309 | H3: =IF(OR(G3="",D3=""),"",G3/D3-1) -> 4.1508585
A4: ='Top 50'!A4 -> 3 | B4: ='Top 50'!C4 -> Augustus Wood Library Bookshelf | C4: ='Top 50'!D4 -> Bookshelf | D4: =IF('Top 50'!H4="","",'Top 50'!H4) -> 799.99 | E4: S9 | F4: =IF(E4="","",INDEX($B$56:$B$66,MATCH(E4,$A$56:$A$66,0))) -> Bookshelf 5-tier 185 cm | G4: =IF(E4="","",INDEX($C$56:$C$66,MATCH(E4,$A$56:$A$66,0))) -> 739 | H4: =IF(OR(G4="",D4=""),"",G4/D4-1) -> -0.076238453 | I4: Conservative comp
A5: ='Top 50'!A5 -> 4 | B5: ='Top 50'!C5 -> Sansur Rustic Pecan Live Edge Wood Console Table | C5: ='Top 50'!D5 -> Console table | D5: =IF('Top 50'!H5="","",'Top 50'!H5) -> 174.99 | E5: S7 | F5: =IF(E5="","",INDEX($B$56:$B$66,MATCH(E5,$A$56:$A$66,0))) -> Console 120 | G5: =IF(E5="","",INDEX($C$56:$C$66,MATCH(E5,$A$56:$A$66,0))) -> 559 | H5: =IF(OR(G5="",D5=""),"",G5/D5-1) -> 2.1944683 | I5: Entryway console
A6: ='Top 50'!A6 -> 5 | B6: ='Top 50'!C6 -> Extra Large Acacia Wood Paddle Cutting Board | C6: ='Top 50'!D6 -> Kitchen & serveware | D6: =IF('Top 50'!H6="","",'Top 50'!H6) -> 59.99 | E6: S11 | F6: =IF(E6="","",INDEX($B$56:$B$66,MATCH(E6,$A$56:$A$66,0))) -> Kitchen gift set (tray + board + spoon) | G6: =IF(E6="","",INDEX($C$56:$C$66,MATCH(E6,$A$56:$A$66,0))) -> 109 | H6: =IF(OR(G6="",D6=""),"",G6/D6-1) -> 0.81696949 | I6: Comp is a single board/tray/bowl, our S11 is a 3-piece personalised gift set: compare as add-on, not like-for-like
A7: ='Top 50'!A7 -> 6 | B7: ='Top 50'!C7 -> Colette Round Wood Ottoman Tray | C7: ='Top 50'!D7 -> Kitchen & serveware | D7: =IF('Top 50'!H7="","",'Top 50'!H7) -> 69.99 | E7: S11 | F7: =IF(E7="","",INDEX($B$56:$B$66,MATCH(E7,$A$56:$A$66,0))) -> Kitchen gift set (tray + board + spoon) | G7: =IF(E7="","",INDEX($C$56:$C$66,MATCH(E7,$A$56:$A$66,0))) -> 109 | H7: =IF(OR(G7="",D7=""),"",G7/D7-1) -> 0.55736534 | I7: Single large tray; our set includes tray+board+spoon
A8: ='Top 50'!A8 -> 7 | B8: ='Top 50'!C8 -> Teakhaus Large Edge Grain Wood Trencher Cutting Board | C8: ='Top 50'!D8 -> Kitchen & serveware | D8: =IF('Top 50'!H8="","",'Top 50'!H8) -> 42.99 | E8: S11 | F8: =IF(E8="","",INDEX($B$56:$B$66,MATCH(E8,$A$56:$A$66,0))) -> Kitchen gift set (tray + board + spoon) | G8: =IF(E8="","",INDEX($C$56:$C$66,MATCH(E8,$A$56:$A$66,0))) -> 109 | H8: =IF(OR(G8="",D8=""),"",G8/D8-1) -> 1.5354734 | I8: Comp is a single board/tray/bowl, our S11 is a 3-piece personalised gift set: compare as add-on, not like-for-like
A9: ='Top 50'!A9 -> 8 | B9: ='Top 50'!C9 -> Dane Acacia Mid Century Modular Bookshelf with Cabinet | C9: ='Top 50'!D9 -> Bookshelf | D9: =IF('Top 50'!H9="","",'Top 50'!H9) -> 649.99 | E9: S9 | F9: =IF(E9="","",INDEX($B$56:$B$66,MATCH(E9,$A$56:$A$66,0))) -> Bookshelf 5-tier 185 cm | G9: =IF(E9="","",INDEX($C$56:$C$66,MATCH(E9,$A$56:$A$66,0))) -> 739 | H9: =IF(OR(G9="",D9=""),"",G9/D9-1) -> 0.13694057 | I9: Conservative comp
A10: ='Top 50'!A10 -> 9 | B10: ='Top 50'!C10 -> Lansing Hazelnut Mango Wood Asymmetrical Side Table | C10: ='Top 50'!D10 -> Side / end table | D10: =IF('Top 50'!H10="","",'Top 50'!H10) -> 149.99 | E10: S6 | F10: =IF(E10="","",INDEX($B$56:$B$66,MATCH(E10,$A$56:$A$66,0))) -> Side table | G10: =IF(E10="","",INDEX($C$56:$C$66,MATCH(E10,$A$56:$A$66,0))) -> 309 | H10: =IF(OR(G10="",D10=""),"",G10/D10-1) -> 1.0601373
A11: ='Top 50'!A11 -> 10 | B11: ='Top 50'!C11 -> Tunisian Olive Wood Cutting Board | C11: ='Top 50'!D11 -> Kitchen & serveware | D11: =IF('Top 50'!H11="","",'Top 50'!H11) -> 29.99 | E11: S11 | F11: =IF(E11="","",INDEX($B$56:$B$66,MATCH(E11,$A$56:$A$66,0))) -> Kitchen gift set (tray + board + spoon) | G11: =IF(E11="","",INDEX($C$56:$C$66,MATCH(E11,$A$56:$A$66,0))) -> 109 | H11: =IF(OR(G11="",D11=""),"",G11/D11-1) -> 2.6345448 | I11: Comp is a single board/tray/bowl, our S11 is a 3-piece personalised gift set: compare as add-on, not like-for-like
A12: ='Top 50'!A12 -> 11 | B12: ='Top 50'!C12 -> CRAFT Avni Arched Natural Carved Wood Floral Storage Cabinet | C12: ='Top 50'!D12 -> Storage cabinet / chest | D12: =IF('Top 50'!H12="","",'Top 50'!H12) -> 1499.99 | F12: =IF(E12="","",INDEX($B$56:$B$66,MATCH(E12,$A$56:$A$66,0))) | G12: =IF(E12="","",INDEX($C$56:$C$66,MATCH(E12,$A$56:$A$66,0))) | H12: =IF(OR(G12="",D12=""),"",G12/D12-1) | I12: No starter-catalogue equivalent (excluded in doc 03 section 6 or not in range)
A13: ='Top 50'!A13 -> 12 | B13: ='Top 50'!C13 -> Paulownia Wood Tripod Plant Stand | C13: ='Top 50'!D13 -> Planter / plant stand | D13: =IF('Top 50'!H13="","",'Top 50'!H13) -> 29.99 | F13: =IF(E13="","",INDEX($B$56:$B$66,MATCH(E13,$A$56:$A$66,0))) | G13: =IF(E13="","",INDEX($C$56:$C$66,MATCH(E13,$A$56:$A$66,0))) | H13: =IF(OR(G13="",D13=""),"",G13/D13-1) | I13: No starter-catalogue equivalent (excluded in doc 03 section 6 or not in range)
A14: ='Top 50'!A14 -> 13 | B14: ='Top 50'!C14 -> Mango Wood Footed Serving Tray | C14: ='Top 50'!D14 -> Kitchen & serveware | D14: =IF('Top 50'!H14="","",'Top 50'!H14) -> 34.99 | E14: S11 | F14: =IF(E14="","",INDEX($B$56:$B$66,MATCH(E14,$A$56:$A$66,0))) -> Kitchen gift set (tray + board + spoon) | G14: =IF(E14="","",INDEX($C$56:$C$66,MATCH(E14,$A$56:$A$66,0))) -> 109 | H14: =IF(OR(G14="",D14=""),"",G14/D14-1) -> 2.1151758 | I14: Comp is a single board/tray/bowl, our S11 is a 3-piece personalised gift set: compare as add-on, not like-for-like
A15: ='Top 50'!A15 -> 14 | B15: ='Top 50'!C15 -> Anish Round Natural Wood Ribbed Pedestal Side Table | C15: ='Top 50'!D15 -> Side / end table | D15: =IF('Top 50'!H15="","",'Top 50'!H15) -> 149.99 | E15: S6 | F15: =IF(E15="","",INDEX($B$56:$B$66,MATCH(E15,$A$56:$A$66,0))) -> Side table | G15: =IF(E15="","",INDEX($C$56:$C$66,MATCH(E15,$A$56:$A$66,0))) -> 309 | H15: =IF(OR(G15="",D15=""),"",G15/D15-1) -> 1.0601373
A16: ='Top 50'!A16 -> 15 | B16: ='Top 50'!C16 -> CRAFT Short Teal Carved Wood Peacock Storage Cabinet | C16: ='Top 50'!D16 -> Storage cabinet / chest | D16: =IF('Top 50'!H16="","",'Top 50'!H16) -> 699.99 | F16: =IF(E16="","",INDEX($B$56:$B$66,MATCH(E16,$A$56:$A$66,0))) | G16: =IF(E16="","",INDEX($C$56:$C$66,MATCH(E16,$A$56:$A$66,0))) | H16: =IF(OR(G16="",D16=""),"",G16/D16-1) | I16: No starter-catalogue equivalent (excluded in doc 03 section 6 or not in range)
A17: ='Top 50'!A17 -> 16 | B17: ='Top 50'!C17 -> Thailand Acacia Wood Serving Bowl | C17: ='Top 50'!D17 -> Kitchen & serveware | D17: =IF('Top 50'!H17="","",'Top 50'!H17) -> 27.98 | E17: S11 | F17: =IF(E17="","",INDEX($B$56:$B$66,MATCH(E17,$A$56:$A$66,0))) -> Kitchen gift set (tray + board + spoon) | G17: =IF(E17="","",INDEX($C$56:$C$66,MATCH(E17,$A$56:$A$66,0))) -> 109 | H17: =IF(OR(G17="",D17=""),"",G17/D17-1) -> 2.8956397 | I17: Comp is a single board/tray/bowl, our S11 is a 3-piece personalised gift set: compare as add-on, not like-for-like
A18: ='Top 50'!A18 -> 17 | B18: ='Top 50'!C18 -> CRAFT Multicolor Carved Wood Elephant Floor Decor | C18: ='Top 50'!D18 -> Décor figure | D18: =IF('Top 50'!H18="","",'Top 50'!H18) -> 249.99 | F18: =IF(E18="","",INDEX($B$56:$B$66,MATCH(E18,$A$56:$A$66,0))) | G18: =IF(E18="","",INDEX($C$56:$C$66,MATCH(E18,$A$56:$A$66,0))) | H18: =IF(OR(G18="",D18=""),"",G18/D18-1) | I18: No starter-catalogue equivalent (excluded in doc 03 section 6 or not in range)
A19: ='Top 50'!A19 -> 18 | B19: ='Top 50'!C19 -> Brentwood Round Natural Wood Pedestal End Table | C19: ='Top 50'!D19 -> Side / end table | D19: =IF('Top 50'!H19="","",'Top 50'!H19) -> 149.99 | E19: S6 | F19: =IF(E19="","",INDEX($B$56:$B$66,MATCH(E19,$A$56:$A$66,0))) -> Side table | G19: =IF(E19="","",INDEX($C$56:$C$66,MATCH(E19,$A$56:$A$66,0))) -> 309 | H19: =IF(OR(G19="",D19=""),"",G19/D19-1) -> 1.0601373
A20: ='Top 50'!A20 -> 19 | B20: ='Top 50'!C20 -> Carved Mango Wood Group of Figures Decor | C20: ='Top 50'!D20 -> Décor figure | D20: =IF('Top 50'!H20="","",'Top 50'!H20) -> 89.99 | F20: =IF(E20="","",INDEX($B$56:$B$66,MATCH(E20,$A$56:$A$66,0))) | G20: =IF(E20="","",INDEX($C$56:$C$66,MATCH(E20,$A$56:$A$66,0))) | H20: =IF(OR(G20="",D20=""),"",G20/D20-1) | I20: No starter-catalogue equivalent (excluded in doc 03 section 6 or not in range)
A21: ='Top 50'!A21 -> 20 | B21: ='Top 50'!C21 -> White Wooden Pooja Mandir with Brass Bells & Doors | C21: ='Top 50'!D21 -> Mandir / pooja unit | D21: =IF('Top 50'!H21="","",'Top 50'!H21) -> 390 | E21: S1 | F21: =IF(E21="","",INDEX($B$56:$B$66,MATCH(E21,$A$56:$A$66,0))) -> Carved mandir 2.5 ft | G21: =IF(E21="","",INDEX($C$56:$C$66,MATCH(E21,$A$56:$A$66,0))) -> 599 | H21: =IF(OR(G21="",D21=""),"",G21/D21-1) -> 0.53589744 | I21: 30 in class (= our 2.5 ft); comp is hand-painted mango; ours is carved
A22: ='Top 50'!A22 -> 21 | B22: ='Top 50'!C22 -> 5' x 2' Natural Teak Finish Mandir with doors | C22: ='Top 50'!D22 -> Mandir / pooja unit | D22: =IF('Top 50'!H22="","",'Top 50'!H22) -> 899 | F22: =IF(E22="","",INDEX($B$56:$B$66,MATCH(E22,$A$56:$A$66,0))) | G22: =IF(E22="","",INDEX($C$56:$C$66,MATCH(E22,$A$56:$A$66,0))) | H22: =IF(OR(G22="",D22=""),"",G22/D22-1) | I22: Larger 4-5 ft unit; we sell 3-4 ft only as made-to-order (doc 08), no starter SKU
A23: ='Top 50'!A23 -> 22 | B23: ='Top 50'!C23 -> Wooden White Pooja Chowki - 18x18x6.5-Inches Gold Bajot | C23: ='Top 50'!D23 -> Pooja stool / chowki | D23: =IF('Top 50'!H23="","",'Top 50'!H23) -> 126 | E23: S10 | F23: =IF(E23="","",INDEX($B$56:$B$66,MATCH(E23,$A$56:$A$66,0))) -> Carved pooja stool | G23: =IF(E23="","",INDEX($C$56:$C$66,MATCH(E23,$A$56:$A$66,0))) -> 189 | H23: =IF(OR(G23="",D23=""),"",G23/D23-1) -> 0.5
A24: ='Top 50'!A24 -> 23 | B24: ='Top 50'!C24 -> Hand-Painted Jharokha Mirror – 12x10 Inches, 8 Colours | C24: ='Top 50'!D24 -> Jharokha / carved wall piece | D24: =IF('Top 50'!H24="","",'Top 50'!H24) -> 60 | E24: S4 | F24: =IF(E24="","",INDEX($B$56:$B$66,MATCH(E24,$A$56:$A$66,0))) -> Jaali wall panel 60 x 90 | G24: =IF(E24="","",INDEX($C$56:$C$66,MATCH(E24,$A$56:$A$66,0))) -> 219 | H24: =IF(OR(G24="",D24=""),"",G24/D24-1) -> 2.65 | I24: Comp is a small MDF painted jharokha, not a solid carved panel; size and material differ from S4
A25: ='Top 50'!A25 -> 24 | B25: ='Top 50'!C25 -> Cordoba Vintage Carved Mirror | C25: ='Top 50'!D25 -> Carved / wooden mirror | D25: =IF('Top 50'!H25="","",'Top 50'!H25) -> 500 | E25: S3 | F25: =IF(E25="","",INDEX($B$56:$B$66,MATCH(E25,$A$56:$A$66,0))) -> Carved mirror 60 x 90 | G25: =IF(E25="","",INDEX($C$56:$C$66,MATCH(E25,$A$56:$A$66,0))) -> 279 | H25: =IF(OR(G25="",D25=""),"",G25/D25-1) -> -0.442 | I25: Wall mirror; check size/material vs S3 (60x90 cm carved)
A26: ='Top 50'!A26 -> 25 | B26: ='Top 50'!C26 -> Agra Reclaimed Wood Mirror | C26: ='Top 50'!D26 -> Carved / wooden mirror | D26: =IF('Top 50'!H26="","",'Top 50'!H26) -> 499.99 | E26: S3 | F26: =IF(E26="","",INDEX($B$56:$B$66,MATCH(E26,$A$56:$A$66,0))) -> Carved mirror 60 x 90 | G26: =IF(E26="","",INDEX($C$56:$C$66,MATCH(E26,$A$56:$A$66,0))) -> 279 | H26: =IF(OR(G26="",D26=""),"",G26/D26-1) -> -0.44198884 | I26: Wall mirror; check size/material vs S3 (60x90 cm carved)
A27: ='Top 50'!A27 -> 26 | B27: ='Top 50'!C27 -> Handcrafted Reclaimed Wood Wall Mirror – Rustic Rectangular Farmhouse Décor for Bathroom, Bedroom and Entryway | C27: ='Top 50'!D27 -> Carved / wooden mirror | D27: =IF('Top 50'!H27="","",'Top 50'!H27) -> 103.95 | E27: S3 | F27: =IF(E27="","",INDEX($B$56:$B$66,MATCH(E27,$A$56:$A$66,0))) -> Carved mirror 60 x 90 | G27: =IF(E27="","",INDEX($C$56:$C$66,MATCH(E27,$A$56:$A$66,0))) -> 279 | H27: =IF(OR(G27="",D27=""),"",G27/D27-1) -> 1.6839827 | I27: Wall mirror; check size/material vs S3 (60x90 cm carved)
A28: ='Top 50'!A28 -> 27 | B28: ='Top 50'!C28 -> Mango Wood Coffee Table | C28: ='Top 50'!D28 -> Coffee table | D28: =IF('Top 50'!H28="","",'Top 50'!H28) -> 799.99 | E28: S5 | F28: =IF(E28="","",INDEX($B$56:$B$66,MATCH(E28,$A$56:$A$66,0))) -> Coffee table 90 x 50 | G28: =IF(E28="","",INDEX($C$56:$C$66,MATCH(E28,$A$56:$A$66,0))) -> 459 | H28: =IF(OR(G28="",D28=""),"",G28/D28-1) -> -0.42624283 | I28: Boutique tier; do not price against commodity
A29: ='Top 50'!A29 -> 28 | B29: ='Top 50'!C29 -> Rustic Low Coffee Table | C29: ='Top 50'!D29 -> Coffee table | D29: =IF('Top 50'!H29="","",'Top 50'!H29) -> 789.25 | E29: S5 | F29: =IF(E29="","",INDEX($B$56:$B$66,MATCH(E29,$A$56:$A$66,0))) -> Coffee table 90 x 50 | G29: =IF(E29="","",INDEX($C$56:$C$66,MATCH(E29,$A$56:$A$66,0))) -> 459 | H29: =IF(OR(G29="",D29=""),"",G29/D29-1) -> -0.41843522 | I29: Boutique tier; do not price against commodity
A30: ='Top 50'!A30 -> 29 | B30: ='Top 50'!C30 -> Solid Natural Mango Wood Bench - 60" | C30: ='Top 50'!D30 -> Bench | D30: =IF('Top 50'!H30="","",'Top 50'!H30) -> 399.99 | E30: S8 | F30: =IF(E30="","",INDEX($B$56:$B$66,MATCH(E30,$A$56:$A$66,0))) -> Bench 120 | G30: =IF(E30="","",INDEX($C$56:$C$66,MATCH(E30,$A$56:$A$66,0))) -> 369 | H30: =IF(OR(G30="",D30=""),"",G30/D30-1) -> -0.077476937
A31: ='Top 50'!A31 -> 30 | B31: ='Top 50'!C31 -> Solid Mango Wood Tall Bookcase | C31: ='Top 50'!D31 -> Bookshelf | D31: =IF('Top 50'!H31="","",'Top 50'!H31) -> 799.99 | E31: S9 | F31: =IF(E31="","",INDEX($B$56:$B$66,MATCH(E31,$A$56:$A$66,0))) -> Bookshelf 5-tier 185 cm | G31: =IF(E31="","",INDEX($C$56:$C$66,MATCH(E31,$A$56:$A$66,0))) -> 739 | H31: =IF(OR(G31="",D31=""),"",G31/D31-1) -> -0.076238453 | I31: Conservative comp
A32: ='Top 50'!A32 -> 31 | B32: ='Top 50'!C32 -> Blayne 78-Inch Tall Live Edge Bookshelf | C32: ='Top 50'!D32 -> Bookshelf | D32: =IF('Top 50'!H32="","",'Top 50'!H32) -> 1095 | E32: S9 | F32: =IF(E32="","",INDEX($B$56:$B$66,MATCH(E32,$A$56:$A$66,0))) -> Bookshelf 5-tier 185 cm | G32: =IF(E32="","",INDEX($C$56:$C$66,MATCH(E32,$A$56:$A$66,0))) -> 739 | H32: =IF(OR(G32="",D32=""),"",G32/D32-1) -> -0.32511416 | I32: Conservative comp
A33: ='Top 50'!A33 -> 32 | B33: ='Top 50'!C33 -> Carved Wooden Mirror | C33: ='Top 50'!D33 -> Carved / wooden mirror | D33: =IF('Top 50'!H33="","",'Top 50'!H33) -> 1171.99 | E33: S3 | F33: =IF(E33="","",INDEX($B$56:$B$66,MATCH(E33,$A$56:$A$66,0))) -> Carved mirror 60 x 90 | G33: =IF(E33="","",INDEX($C$56:$C$66,MATCH(E33,$A$56:$A$66,0))) -> 279 | H33: =IF(OR(G33="",D33=""),"",G33/D33-1) -> -0.76194336 | I33: Wall mirror; check size/material vs S3 (60x90 cm carved)
A34: ='Top 50'!A34 -> 33 | B34: ='Top 50'!C34 -> Summit 54" Modern Coffee Table in Capri Sheesham | C34: ='Top 50'!D34 -> Coffee table | D34: =IF('Top 50'!H34="","",'Top 50'!H34) -> 824 | E34: S5 | F34: =IF(E34="","",INDEX($B$56:$B$66,MATCH(E34,$A$56:$A$66,0))) -> Coffee table 90 x 50 | G34: =IF(E34="","",INDEX($C$56:$C$66,MATCH(E34,$A$56:$A$66,0))) -> 459 | H34: =IF(OR(G34="",D34=""),"",G34/D34-1) -> -0.44296117 | I34: Boutique tier; do not price against commodity
A35: ='Top 50'!A35 -> 34 | B35: ='Top 50'!C35 -> Timbergirl Old reclaimed wood Console Table | C35: ='Top 50'!D35 -> Console table | D35: =IF('Top 50'!H35="","",'Top 50'!H35) -> 799.99 | E35: S7 | F35: =IF(E35="","",INDEX($B$56:$B$66,MATCH(E35,$A$56:$A$66,0))) -> Console 120 | G35: =IF(E35="","",INDEX($C$56:$C$66,MATCH(E35,$A$56:$A$66,0))) -> 559 | H35: =IF(OR(G35="",D35=""),"",G35/D35-1) -> -0.30124127 | I35: Entryway console
A36: ='Top 50'!A36 -> 35 | B36: ='Top 50'!C36 -> Timbergirl Suman Rustic Multicolor Bench - 50" | C36: ='Top 50'!D36 -> Bench | D36: =IF('Top 50'!H36="","",'Top 50'!H36) -> 329.99 | E36: S8 | F36: =IF(E36="","",INDEX($B$56:$B$66,MATCH(E36,$A$56:$A$66,0))) -> Bench 120 | G36: =IF(E36="","",INDEX($C$56:$C$66,MATCH(E36,$A$56:$A$66,0))) -> 369 | H36: =IF(OR(G36="",D36=""),"",G36/D36-1) -> 0.1182157
A37: ='Top 50'!A37 -> 36 | B37: ='Top 50'!C37 -> White and Gold Wall Hanging Pooja Mandir | C37: ='Top 50'!D37 -> Mandir / pooja unit | D37: =IF('Top 50'!H37="","",'Top 50'!H37) -> 275 | E37: S2 | F37: =IF(E37="","",INDEX($B$56:$B$66,MATCH(E37,$A$56:$A$66,0))) -> Compact mandir 2 ft | G37: =IF(E37="","",INDEX($C$56:$C$66,MATCH(E37,$A$56:$A$66,0))) -> 449 | H37: =IF(OR(G37="",D37=""),"",G37/D37-1) -> 0.63272727 | I37: Compact/wall-hanging class; our S2 is solid carved (comp is painted mango, 275-380 sizes)
A38: ='Top 50'!A38 -> 37 | B38: ='Top 50'!C38 -> 5' x 2' White Wooden Pooja Mandir with Doors for Home | C38: ='Top 50'!D38 -> Mandir / pooja unit | D38: =IF('Top 50'!H38="","",'Top 50'!H38) -> 1099 | F38: =IF(E38="","",INDEX($B$56:$B$66,MATCH(E38,$A$56:$A$66,0))) | G38: =IF(E38="","",INDEX($C$56:$C$66,MATCH(E38,$A$56:$A$66,0))) | H38: =IF(OR(G38="",D38=""),"",G38/D38-1) | I38: Larger 4-5 ft unit; we sell 3-4 ft only as made-to-order (doc 08), no starter SKU
A39: ='Top 50'!A39 -> 38 | B39: ='Top 50'!C39 -> Rajasthani Jharokha Mirror with Opening Doors – 20x16 Inches | C39: ='Top 50'!D39 -> Jharokha / carved wall piece | D39: =IF('Top 50'!H39="","",'Top 50'!H39) -> 160 | E39: S4 | F39: =IF(E39="","",INDEX($B$56:$B$66,MATCH(E39,$A$56:$A$66,0))) -> Jaali wall panel 60 x 90 | G39: =IF(E39="","",INDEX($C$56:$C$66,MATCH(E39,$A$56:$A$66,0))) -> 219 | H39: =IF(OR(G39="",D39=""),"",G39/D39-1) -> 0.36875 | I39: Comp is a small MDF painted jharokha, not a solid carved panel; size and material differ from S4
A40: ='Top 50'!A40 -> 39 | B40: ='Top 50'!C40 -> Seesham Wood Coffee Table | C40: ='Top 50'!D40 -> Coffee table | D40: =IF('Top 50'!H40="","",'Top 50'!H40) -> 599.99 | E40: S5 | F40: =IF(E40="","",INDEX($B$56:$B$66,MATCH(E40,$A$56:$A$66,0))) -> Coffee table 90 x 50 | G40: =IF(E40="","",INDEX($C$56:$C$66,MATCH(E40,$A$56:$A$66,0))) -> 459 | H40: =IF(OR(G40="",D40=""),"",G40/D40-1) -> -0.23498725 | I40: Boutique tier; do not price against commodity
...

Sheet Category summary
A1: Category | B1: Count | C1: Min price (USD) | D1: Median price (USD) | E1: Max price (USD) | F1: Our SKU | G1: Our planned price (USD) | H1: Our price vs median
A2: Console table | B2: =COUNTIF('Top 50'!$D$2:$D$51,A2) -> 4 | C2: =_xlfn.MINIFS('Top 50'!$H$2:$H$51,'Top 50'!$D$2:$D$51,A2) -> 174.99 | D2: {=MEDIAN(IF(('Top 50'!$D$2:$D$51=A2)*ISNUMBER('Top 50'!$H$2:$H$51),'Top 50'!$H$2:$H$51))} -> 540.31 | E2: =_xlfn.MAXIFS('Top 50'!$H$2:$H$51,'Top 50'!$D$2:$D$51,A2) -> 799.99 | F2: S7 | G2: =IF(F2="","",INDEX('Our target'!$C$56:$C$66,MATCH(F2,'Our target'!$A$56:$A$66,0))) -> 559 | H2: =IF(OR(G2="",D2=""),"",G2/D2-1) -> 0.034591253
A3: Side / end table | B3: =COUNTIF('Top 50'!$D$2:$D$51,A3) -> 4 | C3: =_xlfn.MINIFS('Top 50'!$H$2:$H$51,'Top 50'!$D$2:$D$51,A3) -> 59.99 | D3: {=MEDIAN(IF(('Top 50'!$D$2:$D$51=A3)*ISNUMBER('Top 50'!$H$2:$H$51),'Top 50'!$H$2:$H$51))} -> 149.99 | E3: =_xlfn.MAXIFS('Top 50'!$H$2:$H$51,'Top 50'!$D$2:$D$51,A3) -> 149.99 | F3: S6 | G3: =IF(F3="","",INDEX('Our target'!$C$56:$C$66,MATCH(F3,'Our target'!$A$56:$A$66,0))) -> 309 | H3: =IF(OR(G3="",D3=""),"",G3/D3-1) -> 1.0601373
A4: Bookshelf | B4: =COUNTIF('Top 50'!$D$2:$D$51,A4) -> 4 | C4: =_xlfn.MINIFS('Top 50'!$H$2:$H$51,'Top 50'!$D$2:$D$51,A4) -> 649.99 | D4: {=MEDIAN(IF(('Top 50'!$D$2:$D$51=A4)*ISNUMBER('Top 50'!$H$2:$H$51),'Top 50'!$H$2:$H$51))} -> 799.99 | E4: =_xlfn.MAXIFS('Top 50'!$H$2:$H$51,'Top 50'!$D$2:$D$51,A4) -> 1095 | F4: S9 | G4: =IF(F4="","",INDEX('Our target'!$C$56:$C$66,MATCH(F4,'Our target'!$A$56:$A$66,0))) -> 739 | H4: =IF(OR(G4="",D4=""),"",G4/D4-1) -> -0.076238453
A5: Kitchen & serveware | B5: =COUNTIF('Top 50'!$D$2:$D$51,A5) -> 6 | C5: =_xlfn.MINIFS('Top 50'!$H$2:$H$51,'Top 50'!$D$2:$D$51,A5) -> 27.98 | D5: {=MEDIAN(IF(('Top 50'!$D$2:$D$51=A5)*ISNUMBER('Top 50'!$H$2:$H$51),'Top 50'!$H$2:$H$51))} -> 38.99 | E5: =_xlfn.MAXIFS('Top 50'!$H$2:$H$51,'Top 50'!$D$2:$D$51,A5) -> 69.99 | F5: S11 | G5: =IF(F5="","",INDEX('Our target'!$C$56:$C$66,MATCH(F5,'Our target'!$A$56:$A$66,0))) -> 109 | H5: =IF(OR(G5="",D5=""),"",G5/D5-1) -> 1.7955886
A6: Storage cabinet / chest | B6: =COUNTIF('Top 50'!$D$2:$D$51,A6) -> 3 | C6: =_xlfn.MINIFS('Top 50'!$H$2:$H$51,'Top 50'!$D$2:$D$51,A6) -> 479.99 | D6: {=MEDIAN(IF(('Top 50'!$D$2:$D$51=A6)*ISNUMBER('Top 50'!$H$2:$H$51),'Top 50'!$H$2:$H$51))} -> 699.99 | E6: =_xlfn.MAXIFS('Top 50'!$H$2:$H$51,'Top 50'!$D$2:$D$51,A6) -> 1499.99 | G6: =IF(F6="","",INDEX('Our target'!$C$56:$C$66,MATCH(F6,'Our target'!$A$56:$A$66,0))) | H6: =IF(OR(G6="",D6=""),"",G6/D6-1)
A7: Planter / plant stand | B7: =COUNTIF('Top 50'!$D$2:$D$51,A7) -> 1 | C7: =_xlfn.MINIFS('Top 50'!$H$2:$H$51,'Top 50'!$D$2:$D$51,A7) -> 29.99 | D7: {=MEDIAN(IF(('Top 50'!$D$2:$D$51=A7)*ISNUMBER('Top 50'!$H$2:$H$51),'Top 50'!$H$2:$H$51))} -> 29.99 | E7: =_xlfn.MAXIFS('Top 50'!$H$2:$H$51,'Top 50'!$D$2:$D$51,A7) -> 29.99 | G7: =IF(F7="","",INDEX('Our target'!$C$56:$C$66,MATCH(F7,'Our target'!$A$56:$A$66,0))) | H7: =IF(OR(G7="",D7=""),"",G7/D7-1)
A8: Décor figure | B8: =COUNTIF('Top 50'!$D$2:$D$51,A8) -> 2 | C8: =_xlfn.MINIFS('Top 50'!$H$2:$H$51,'Top 50'!$D$2:$D$51,A8) -> 89.99 | D8: {=MEDIAN(IF(('Top 50'!$D$2:$D$51=A8)*ISNUMBER('Top 50'!$H$2:$H$51),'Top 50'!$H$2:$H$51))} -> 169.99 | E8: =_xlfn.MAXIFS('Top 50'!$H$2:$H$51,'Top 50'!$D$2:$D$51,A8) -> 249.99 | G8: =IF(F8="","",INDEX('Our target'!$C$56:$C$66,MATCH(F8,'Our target'!$A$56:$A$66,0))) | H8: =IF(OR(G8="",D8=""),"",G8/D8-1)
A9: Mandir / pooja unit | B9: =COUNTIF('Top 50'!$D$2:$D$51,A9) -> 7 | C9: =_xlfn.MINIFS('Top 50'!$H$2:$H$51,'Top 50'!$D$2:$D$51,A9) -> 275 | D9: {=MEDIAN(IF(('Top 50'!$D$2:$D$51=A9)*ISNUMBER('Top 50'!$H$2:$H$51),'Top 50'!$H$2:$H$51))} -> 395 | E9: =_xlfn.MAXIFS('Top 50'!$H$2:$H$51,'Top 50'!$D$2:$D$51,A9) -> 1399 | F9: S1 | G9: =IF(F9="","",INDEX('Our target'!$C$56:$C$66,MATCH(F9,'Our target'!$A$56:$A$66,0))) -> 599 | H9: =IF(OR(G9="",D9=""),"",G9/D9-1) -> 0.5164557
A10: Pooja stool / chowki | B10: =COUNTIF('Top 50'!$D$2:$D$51,A10) -> 2 | C10: =_xlfn.MINIFS('Top 50'!$H$2:$H$51,'Top 50'!$D$2:$D$51,A10) -> 126 | D10: {=MEDIAN(IF(('Top 50'!$D$2:$D$51=A10)*ISNUMBER('Top 50'!$H$2:$H$51),'Top 50'!$H$2:$H$51))} -> 130.5 | E10: =_xlfn.MAXIFS('Top 50'!$H$2:$H$51,'Top 50'!$D$2:$D$51,A10) -> 135 | F10: S10 | G10: =IF(F10="","",INDEX('Our target'!$C$56:$C$66,MATCH(F10,'Our target'!$A$56:$A$66,0))) -> 189 | H10: =IF(OR(G10="",D10=""),"",G10/D10-1) -> 0.44827586
A11: Jharokha / carved wall piece | B11: =COUNTIF('Top 50'!$D$2:$D$51,A11) -> 3 | C11: =_xlfn.MINIFS('Top 50'!$H$2:$H$51,'Top 50'!$D$2:$D$51,A11) -> 60 | D11: {=MEDIAN(IF(('Top 50'!$D$2:$D$51=A11)*ISNUMBER('Top 50'!$H$2:$H$51),'Top 50'!$H$2:$H$51))} -> 80 | E11: =_xlfn.MAXIFS('Top 50'!$H$2:$H$51,'Top 50'!$D$2:$D$51,A11) -> 160 | F11: S4 | G11: =IF(F11="","",INDEX('Our target'!$C$56:$C$66,MATCH(F11,'Our target'!$A$56:$A$66,0))) -> 219 | H11: =IF(OR(G11="",D11=""),"",G11/D11-1) -> 1.7375
A12: Carved / wooden mirror | B12: =COUNTIF('Top 50'!$D$2:$D$51,A12) -> 5 | C12: =_xlfn.MINIFS('Top 50'!$H$2:$H$51,'Top 50'!$D$2:$D$51,A12) -> 103.95 | D12: {=MEDIAN(IF(('Top 50'!$D$2:$D$51=A12)*ISNUMBER('Top 50'!$H$2:$H$51),'Top 50'!$H$2:$H$51))} -> 499.99 | E12: =_xlfn.MAXIFS('Top 50'!$H$2:$H$51,'Top 50'!$D$2:$D$51,A12) -> 1171.99 | F12: S3 | G12: =IF(F12="","",INDEX('Our target'!$C$56:$C$66,MATCH(F12,'Our target'!$A$56:$A$66,0))) -> 279 | H12: =IF(OR(G12="",D12=""),"",G12/D12-1) -> -0.44198884
A13: Coffee table | B13: =COUNTIF('Top 50'!$D$2:$D$51,A13) -> 5 | C13: =_xlfn.MINIFS('Top 50'!$H$2:$H$51,'Top 50'!$D$2:$D$51,A13) -> 299.99 | D13: {=MEDIAN(IF(('Top 50'!$D$2:$D$51=A13)*ISNUMBER('Top 50'!$H$2:$H$51),'Top 50'!$H$2:$H$51))} -> 789.25 | E13: =_xlfn.MAXIFS('Top 50'!$H$2:$H$51,'Top 50'!$D$2:$D$51,A13) -> 824 | F13: S5 | G13: =IF(F13="","",INDEX('Our target'!$C$56:$C$66,MATCH(F13,'Our target'!$A$56:$A$66,0))) -> 459 | H13: =IF(OR(G13="",D13=""),"",G13/D13-1) -> -0.41843522
A14: Bench | B14: =COUNTIF('Top 50'!$D$2:$D$51,A14) -> 4 | C14: =_xlfn.MINIFS('Top 50'!$H$2:$H$51,'Top 50'!$D$2:$D$51,A14) -> 279.99 | D14: {=MEDIAN(IF(('Top 50'!$D$2:$D$51=A14)*ISNUMBER('Top 50'!$H$2:$H$51),'Top 50'!$H$2:$H$51))} -> 364.99 | E14: =_xlfn.MAXIFS('Top 50'!$H$2:$H$51,'Top 50'!$D$2:$D$51,A14) -> 947 | F14: S8 | G14: =IF(F14="","",INDEX('Our target'!$C$56:$C$66,MATCH(F14,'Our target'!$A$56:$A$66,0))) -> 369 | H14: =IF(OR(G14="",D14=""),"",G14/D14-1) -> 0.010986602
A15: Total rows / overall | B15: =SUM(B2:B14) -> 50 | C15: =MIN('Top 50'!$H$2:$H$51) -> 27.98 | D15: =MEDIAN('Top 50'!$H$2:$H$51) -> 339.995 | E15: =MAX('Top 50'!$H$2:$H$51) -> 1499.99
A17: Notes: prices are current listed prices (sale price where two show); some are lowest-size variants. Categories with 1-2 rows have no meaningful median. Our planned prices are ASSUMPTIONS from the starter catalogue (03). Categories with no SKU (storage cabinet, planter, decor) are outside the first container.

Sheet Method & caveats
A1: Topic | B1: Detail
A2: Purpose | B2: Internal research list for The Wood Vintage (handcrafted Jodhpur wood furniture and decor; first market USA, B2C): 50 products that appear to sell best in the USA in categories the workshop can make, with current prices and thumbnails. Prepared 2026-09-25.
A3: What 'top selling' means here | B3: There is NO real sales data. Every row is ranked by an observable proxy, stated in the 'Best-seller proxy' column: (a) World Market: public review count and rating, plus the position in World Market's own 'Top Sellers' sort for a search (srule=top-sellers); (b) Shopify retailers (Timbergirl, World Interiors, The Vintage Realm, Urli Utsav Decor, The Mandir Store): position in the retailer's own 'Best selling' collection sort (sort_by=best-selling); these pages show no review counts. A proxy is NOT a unit-sales figure and is not comparable across retailers.
A4: Ranking rule | B4: Rows are ordered by proxy tier, then by review count (highest first), then by best-selling sort position (lowest first). Tier A = 100+ public reviews. Tier B = 20 to 99 reviews, or #1-#3 in a retailer's best-selling sort where no reviews are shown. Tier C = everything else (under 20 reviews or lower sort position). Within a tier the order is only indicative; rank 1 is not proven to outsell rank 2. Category spread was applied on purpose (max 7 rows per category; wide price spread from about USD 27 to USD 1,500), so this is 'best sellers by category' and not a pure global sort.
A5: Which sites were readable | B5: READ: worldmarket.com (search and product pages), timbergirl.com, worldinteriors.com, thevintagerealm.com, urliutsav.com, themandirstore.us (public HTML pages and each store's product .js feed). BLOCKED or unusable (no data taken): Etsy (HTTP 403), Amazon.com (bot-check page; best-seller and search pages return no product data), Wayfair (429), eBay (403), The Home Depot (403), Walmart (JavaScript/captcha shell, no product data), Target (JavaScript-rendered, no product data), Novica (JavaScript-rendered), Overstock (404), Pottery Barn, CB2, Crate and Barrel, West Elm (403/timeouts in earlier research), Jaipur Living (no product feed), Kalalou (no usable feed). Consequence: NO Amazon, Etsy or Wayfair rows. Real marketplace best sellers (Etsy 'Bestseller' badge and sales counts, Amazon Best Sellers Rank) are still missing and remain the biggest gap. Channels are therefore limited to World Market plus five specialist online stores.
A6: Prices | B6: Current price = the price shown on the product page or product feed on the fetched date/time (UTC, column P), in USD, before shipping and tax. 'Sale / list price' is filled only where the page shows a higher list or compare-at price. Where a product has several sizes (The Vintage Realm) the price is the lowest size variant and the row is marked. Sansur console and Indra cabinet are on sale. Prices change daily; re-check before using them for pricing decisions (FAST).
A7: Availability | B7: Timbergirl's #1 coffee table and several other Timbergirl best sellers were SOLD OUT at fetch (that is itself a demand signal, but the price shown is the list price of an unavailable item). The Mandir Store 5 x 2 ft white mandir is on backorder per its own text. Status column says so.
A8: Materials and honesty flags | B8: 'Material (as stated)' is copied or condensed from the seller's page and NOT verified. Several rows are deliberately non-solid or non-Indian so the owner can see the mass-market volume leaders: Everett console (acacia, pine, MDF, plywood, veneer), Chloe side table (rubberwood), Augustus bookshelf (rubber wood and veneer), Urli jharokha mirrors (MDF frame with glass), The Mandir Store mandirs (engineered wood and plywood). Mango vs acacia naming is inconsistent on some World Market pages (Lansing table title says mango, spec says acacia). 'Sheesham' is Dalbergia sissoo (CITES-listed; see starter catalogue section 5).
A9: Data-quality warnings | B9: 1) Proxy is not sales. 2) Review counts at World Market can include reviews for all colours/sizes of a listing. 3) Shopify 'best selling' sort is the store's own ordering and may reflect a time window or manual curation; only the first page of each collection was read. 4) Ratings and review counts are blank for Shopify retailers because none were shown. 5) Images are the seller's main image; dimension text was copied from the page and may be inconsistent (TimorGreen carved mirror lists 2 in high x 81 in long x 45 in wide). 6) Category assignment is ours. 7) Only 1-2 rows in some categories, so medians there are not meaningful.
A10: Image usage | B10: Thumbnails (about 140 px, downscaled JPEG) were downloaded from each seller's product page for INTERNAL reference only. They belong to their owners. Do NOT reuse them on our website, ads, social media or marketplace listings; use our own workshop photos (starter catalogue section 4). Downloads were sequential with about 1 second gaps, one image per product, no bulk crawling.
A11: Our target sheet | B11: Maps each row to the closest starter SKU (S1-S11) in docs/marketing/us-first-100/03-starter-catalogue.md at its planned US price (2026-09-25 assumptions; edit them in the SKU table at the bottom of the 'Our target' sheet). Gap % = our price / competitor price - 1, computed by formula. Blank SKU = no equivalent in the first container. A large gap is not a conclusion: sizes, materials and set contents differ.
A12: Category summary | B12: Counts, min, median and max are live formulas over the 'Top 50' sheet (MINIFS, MAXIFS, MEDIAN with IF array). Change a price and they update. Our planned price and price vs median are pulled from the SKU table.
... A14: Sources | B14: See documentation/docs/marketing/exports/sources/README.md for the URL list and fetch method. Earlier repo research used for context: competitor-research/us-b2c-price-benchmark.md, us-b2c-competitor-analysis.md, marketing/best-selling-products-by-market.md, marketing/us-first-100/03-starter-catalogue.md.
